<?xml version="1.0" encoding="utf-8"?><testsuites><testsuite name="pytest" errors="0" failures="2" skipped="0" tests="4" time="0.775" timestamp="2023-11-28T19:20:54.958368" hostname="haidarova"><testcase classname="tests.test_all.TestAnalysis" name="test_calculate_statistics" file="tests\test_all.py" line="18" time="0.002"><failure message="AssertionError: assert {'count': 5, ...an': 3.0, ...} == {'count': 5, ...an': 3.0, ...}&#10;  Omitting 7 identical items, use -vv to show&#10;  Differing items:&#10;  {'max': 5} != {'max': 2}&#10;  Use -v to get more diff">self = &lt;tests.test_all.TestAnalysis object at 0x00000210E7C32CB0&gt;

    def test_calculate_statistics(self):
        ''' тест функции '''
        arr = np.array([1,2,3,4,5])
        true_dict = {
            "count": 5,
            "sum": 15,
            "mean": 3.0,
            "median": 3.0,
            "min": 1,
            "max": 2,
            "variance": 2.0,
            "standard_deviation": 1.4142135623730951
        }
&gt;       assert analysis.calculate_statistics(arr) == true_dict
E       AssertionError: assert {'count': 5, ...an': 3.0, ...} == {'count': 5, ...an': 3.0, ...}
E         Omitting 7 identical items, use -vv to show
E         Differing items:
E         {'max': 5} != {'max': 2}
E         Use -v to get more diff

tests\test_all.py:32: AssertionError</failure><system-out>--------------------------------- Captured Log ---------------------------------

--------------------------------- Captured Out ---------------------------------

</system-out><system-err>--------------------------------- Captured Err ---------------------------------

</system-err></testcase><testcase classname="tests.test_all.TestAnalysis" name="test_get_partition" file="tests\test_all.py" line="34" time="0.001"><system-out>--------------------------------- Captured Log ---------------------------------

--------------------------------- Captured Out ---------------------------------

</system-out><system-err>--------------------------------- Captured Err ---------------------------------

</system-err></testcase><testcase classname="tests.test_all.TestAnalysis" name="test_number_generation" file="tests\test_all.py" line="40" time="0.145"><failure message="ValueError: The truth value of an array with more than one element is ambiguous. Use a.any() or a.all()">self = &lt;tests.test_all.TestAnalysis object at 0x00000210E7C32E90&gt;

    def test_number_generation(self):
        average = 5.0
        var = 3.0
        size = 10
&gt;       assert analysis.number_generation(average, var, size) == (np.array([5.81923549, 3.81973576, 5.41991753, 2.05423947, 6.30448165,
                                    2.34178466, 5.00888036, 4.79175957, 3.60226639, 9.9741371 ]),
                          np.array([7.30798162, 0.87603514, 7.23150544, 0.10514687, 0.72634391,
                                    0.61803554, 1.85457632, 5.56537148, 3.18600652, 8.46867302]),
                          np.array([6.7314887 , 3.41014754, 5.70307387, 5.03950646, 3.09540968,
                                    2.4742548 , 2.36004233, 3.9579512 , 4.73376682, 4.38187534]))
E       ValueError: The truth value of an array with more than one element is ambiguous. Use a.any() or a.all()

tests\test_all.py:45: ValueError</failure><system-out>--------------------------------- Captured Log ---------------------------------

--------------------------------- Captured Out ---------------------------------

</system-out><system-err>--------------------------------- Captured Err ---------------------------------

</system-err></testcase><testcase classname="tests.test_all.TestAnalysis" name="test_passing" file="tests\test_all.py" line="14" time="0.001"><system-out>--------------------------------- Captured Log ---------------------------------

--------------------------------- Captured Out ---------------------------------

</system-out><system-err>--------------------------------- Captured Err ---------------------------------

</system-err></testcase></testsuite></testsuites>